Workbook

Sheet Movilidad FICT 2023+
B1: Movilidad Entrante | M1: Movilidad Saliente
A2: Mes | B2: Categoría | D2: Total Categoría | E2: Nivel | G2: Total Nivel | H2: Tipo de Actividad | K2: Total Tipo de Actividad | L2: Total Movilidad Entrante | M2: Categoría | O2: Total Categoría | P2: Nivel | R2: Total Nivel | S2: Tipo de Actividad | V2: Total Tipo de Actividad | W2: Total Movilidad Saliente | X2: Total por mes
B3: Académico Entrante | C3: Estudiante Entrante | E3: Grado | F3: Postgrado | H3: Intercambio Académico | I3: Asistencia a Reuniones | J3: Cursos de Formación | M3: Académico Saliente | N3: Estudiante Saliente | P3: Grado | Q3: Postgrado | S3: Intercambio Académico | T3: Asitencia a Reuniones | U3: Cursos de Formación
A4: Enero | D4: =SUM(B4:C4) -> 0 | G4: =SUM(E4:F4) -> 0 | K4: =SUM(H4:J4) -> 0 | L4: =D4+G4+K4 -> 0 | M4: 1 | N4: 1 | O4: =SUM(M4:N4) -> 2 | P4: 2 | R4: =SUM(P4:Q4) -> 2 | S4: 1 | T4: 1 | V4: =SUM(S4:U4) -> 2 | W4: =SUM(M4:N4) -> 2 | X4: =L4+W4 -> 2
A5: Febrero | D5: =SUM(B5:C5) -> 0 | G5: =SUM(E5:F5) -> 0 | K5: =SUM(H5:J5) -> 0 | L5: =SUM(B5:C5) -> 0 | N5: 1 | O5: =SUM(M5:N5) -> 1 | P5: 1 | R5: =SUM(P5:Q5) -> 1 | S5: 1 | V5: =SUM(S5:U5) -> 1 | W5: =SUM(M5:N5) -> 1 | X5: =L5+W5 -> 1
A6: Marzo | B6: 2 | C6: 1 | D6: =SUM(B6:C6) -> 3 | E6: 1 | F6: 2 | G6: =SUM(E6:F6) -> 3 | H6: 1 | J6: 2 | K6: =SUM(H6:J6) -> 3 | L6: =SUM(B6:C6) -> 3 | O6: =SUM(M6:N6) -> 0 | R6: =SUM(P6:Q6) -> 0 | V6: =SUM(S6:U6) -> 0 | W6: =SUM(M6:N6) -> 0 | X6: =L6+W6 -> 3
A7: Abril | D7: =SUM(B7:C7) -> 0 | G7: =SUM(E7:F7) -> 0 | K7: =SUM(H7:J7) -> 0 | L7: =SUM(B7:C7) -> 0 | O7: =SUM(M7:N7) -> 0 | R7: =SUM(P7:Q7) -> 0 | V7: =SUM(S7:U7) -> 0 | W7: =SUM(M7:N7) -> 0 | X7: =L7+W7 -> 0
A8: Mayo | D8: =SUM(B8:C8) -> 0 | G8: =SUM(E8:F8) -> 0 | K8: =SUM(H8:J8) -> 0 | L8: =SUM(B8:C8) -> 0 | M8: 1 | O8: =SUM(M8:N8) -> 1 | P8: 1 | R8: =SUM(P8:Q8) -> 1 | U8: 1 | V8: =SUM(S8:U8) -> 1 | W8: =SUM(M8:N8) -> 1 | X8: =L8+W8 -> 1
A9: Junio | B9: 2 | C9: 39 | D9: =SUM(B9:C9) -> 41 | E9: 41 | G9: =SUM(E9:F9) -> 41 | J9: 41 | K9: =SUM(H9:J9) -> 41 | L9: =SUM(B9:C9) -> 41 | N9: 15 | O9: =SUM(M9:N9) -> 15 | P9: 15 | R9: =SUM(P9:Q9) -> 15 | U9: 15 | V9: =SUM(S9:U9) -> 15 | W9: =SUM(M9:N9) -> 15 | X9: =L9+W9 -> 56
A10: Julio | C10: 2 | D10: =SUM(B10:C10) -> 2 | F10: 2 | G10: =SUM(E10:F10) -> 2 | H10: 2 | K10: =SUM(H10:J10) -> 2 | L10: =SUM(B10:C10) -> 2 | M10: 2 | O10: =SUM(M10:N10) -> 2 | P10: 2 | R10: =SUM(P10:Q10) -> 2 | U10: 2 | V10: =SUM(S10:U10) -> 2 | W10: =SUM(M10:N10) -> 2 | X10: =L10+W10 -> 4
A11: Agosto | D11: =SUM(B11:C11) -> 0 | G11: =SUM(E11:F11) -> 0 | K11: =SUM(H11:J11) -> 0 | L11: =SUM(B11:C11) -> 0 | N11: 7 | O11: =SUM(M11:N11) -> 7 | P11: 7 | R11: =SUM(P11:Q11) -> 7 | S11: 7 | V11: =SUM(S11:U11) -> 7 | W11: =SUM(M11:N11) -> 7 | X11: =L11+W11 -> 7
A12: Septiembre | C12: 8 | D12: =SUM(B12:C12) -> 8 | E12: 8 | G12: =SUM(E12:F12) -> 8 | J12: 8 | K12: =SUM(H12:J12) -> 8 | L12: =SUM(B12:C12) -> 8 | N12: 2 | O12: =SUM(M12:N12) -> 2 | P12: 2 | R12: =SUM(P12:Q12) -> 2 | S12: 1 | T12: 1 | V12: =SUM(S12:U12) -> 2 | W12: =SUM(M12:N12) -> 2 | X12: =L12+W12 -> 10
A13: Octubre | C13: 1 | D13: =SUM(B13:C13) -> 1 | E13: 1 | G13: =SUM(E13:F13) -> 1 | H13: 1 | K13: =SUM(H13:J13) -> 1 | L13: =SUM(B13:C13) -> 1 | O13: =SUM(M13:N13) -> 0 | R13: =SUM(P13:Q13) -> 0 | V13: =SUM(S13:U13) -> 0 | W13: =SUM(M13:N13) -> 0 | X13: =L13+W13 -> 1
A14: Noviembre | D14: =SUM(B14:C14) -> 0 | G14: =SUM(E14:F14) -> 0 | K14: =SUM(H14:J14) -> 0 | L14: =SUM(B14:C14) -> 0 | O14: =SUM(M14:N14) -> 0 | R14: =SUM(P14:Q14) -> 0 | V14: =SUM(S14:U14) -> 0 | W14: =SUM(M14:N14) -> 0 | X14: =L14+W14 -> 0
A15: Diciembre | D15: =SUM(B15:C15) -> 0 | G15: =SUM(E15:F15) -> 0 | K15: =SUM(H15:J15) -> 0 | L15: =SUM(B15:C15) -> 0 | N15: 12 | O15: =SUM(M15:N15) -> 12 | P15: 12 | R15: =SUM(P15:Q15) -> 12 | S15: 12 | V15: =SUM(S15:U15) -> 12 | W15: =SUM(M15:N15) -> 12 | X15: =L15+W15 -> 12
A16: Total por categoría | B16: =SUM(B4:B15) -> 4 | C16: =SUM(C4:C15) -> 51 | D16: =SUM(D4:D15) -> 55 | E16: =SUM(E4:E15) -> 51 | F16: =SUM(F6:F15) -> 4 | G16: =SUM(G4:G15) -> 55 | H16: =SUM(H6:H15) -> 4 | J16: =SUM(J4:J15) -> 51 | K16: =SUM(K4:K15) -> 55 | L16: =SUM(L4:L15) -> 55 | M16: =SUM(M4:M15) -> 4 | N16: =SUM(N4:N15) -> 38 | O16: =SUM(O4:O15) -> 42 | P16: =SUM(P4:P15) -> 42 | R16: =SUM(R4:R15) -> 42 | S16: =SUM(S4:S15) -> 22 | T16: =SUM(T4:T15) -> 2 | U16: =SUM(U8:U15) -> 18 | V16: =SUM(V4:V15) -> 42 | W16: =SUM(W4:W15) -> 42 | X16: =SUM(X4:X15) -> 97
A20: Resumen por año | B20: Tipo de movilidad | D20: Nivel | F20: Categoría | H20: Tipo de Actividad | K20: Modalidad
B21: Movilidad Entrante | C21: Movilidad Saliente | D21: Grado | E21: Postgrado | F21: Estudiantes | G21: Académicos | H21: Intercambio Académico | I21: Asistencia a Reuniones | J21: Cursos de Formación | K21: Virtual | L21: Presencial
B22: =L16 -> 55 | C22: =W16 -> 42 | D22: =E9+E12+E13+P4+P5+P6+P8+P9+P10+P11+P12+P15+E6 -> 93 | E22: =F10+Q6+F6 -> 4 | F22: =C16+N16 -> 89 | G22: =B16+M16 -> 8 | H22: =H6+H10+H13+S4+S5+S11+S12+S15 -> 26 | I22: =T4+T12 -> 2 | J22: =J6+J9+J12+U8+U9+U10 -> 69 | K22: 57 | L22: 40
A23: Total | B23: =B22+C22 -> 97

Sheet Movilidad FICT 2023 (2)
B1: Movilidad Entrante | M1: Movilidad Saliente
A2: Mes | B2: Categoría | D2: Total Categoría | E2: Nivel | G2: Total Nivel | H2: Tipo de Actividad | K2: Total Tipo de Actividad | L2: Total Movilidad Entrante | M2: Categoría | O2: Total Categoría | P2: Nivel | R2: Total Nivel | S2: Tipo de Actividad | V2: Total Tipo de Actividad | W2: Total Movilidad Saliente | X2: Total por mes
B3: Académico Entrante | C3: Estudiante Entrante | E3: Grado | F3: Postgrado | H3: Intercambio Académico | I3: Asistencia a Reuniones | J3: Cursos de Formación | M3: Académico Saliente | N3: Estudiante Saliente | P3: Grado | Q3: Postgrado | S3: Intercambio Académico | T3: Asitencia a Reuniones | U3: Cursos de Formación
A4: Enero | D4: =SUM(B4:C4) -> 0 | G4: =SUM(E4:F4) -> 0 | K4: =SUM(H4:J4) -> 0 | L4: =D4+G4+K4 -> 0 | M4: 1 | N4: 1 | O4: =SUM(M4:N4) -> 2 | P4: 2 | R4: =SUM(P4:Q4) -> 2 | S4: 1 | T4: 1 | V4: =SUM(S4:U4) -> 2 | W4: =SUM(M4:N4) -> 2 | X4: =L4+W4 -> 2
A5: Febrero | D5: =SUM(B5:C5) -> 0 | G5: =SUM(E5:F5) -> 0 | K5: =SUM(H5:J5) -> 0 | L5: =SUM(B5:C5) -> 0 | N5: 1 | O5: =SUM(M5:N5) -> 1 | P5: 1 | R5: =SUM(P5:Q5) -> 1 | S5: 1 | V5: =SUM(S5:U5) -> 1 | W5: =SUM(M5:N5) -> 1 | X5: =L5+W5 -> 1
A6: Marzo | B6: 2 | C6: 1 | D6: =SUM(B6:C6) -> 3 | E6: 1 | F6: 2 | G6: =SUM(E6:F6) -> 3 | H6: 1 | J6: 2 | K6: =SUM(H6:J6) -> 3 | L6: =SUM(B6:C6) -> 3 | O6: =SUM(M6:N6) -> 0 | R6: =SUM(P6:Q6) -> 0 | V6: =SUM(S6:U6) -> 0 | W6: =SUM(M6:N6) -> 0 | X6: =L6+W6 -> 3
A7: Abril | D7: =SUM(B7:C7) -> 0 | G7: =SUM(E7:F7) -> 0 | K7: =SUM(H7:J7) -> 0 | L7: =SUM(B7:C7) -> 0 | O7: =SUM(M7:N7) -> 0 | R7: =SUM(P7:Q7) -> 0 | V7: =SUM(S7:U7) -> 0 | W7: =SUM(M7:N7) -> 0 | X7: =L7+W7 -> 0
A8: Mayo | D8: =SUM(B8:C8) -> 0 | G8: =SUM(E8:F8) -> 0 | K8: =SUM(H8:J8) -> 0 | L8: =SUM(B8:C8) -> 0 | M8: 1 | O8: =SUM(M8:N8) -> 1 | P8: 1 | R8: =SUM(P8:Q8) -> 1 | U8: 1 | V8: =SUM(S8:U8) -> 1 | W8: =SUM(M8:N8) -> 1 | X8: =L8+W8 -> 1
A9: Junio | B9: 2 | C9: 39 | D9: =SUM(B9:C9) -> 41 | E9: 41 | G9: =SUM(E9:F9) -> 41 | J9: 41 | K9: =SUM(H9:J9) -> 41 | L9: =SUM(B9:C9) -> 41 | N9: 15 | O9: =SUM(M9:N9) -> 15 | P9: 15 | R9: =SUM(P9:Q9) -> 15 | U9: 15 | V9: =SUM(S9:U9) -> 15 | W9: =SUM(M9:N9) -> 15 | X9: =L9+W9 -> 56
A10: Julio | C10: 2 | D10: =SUM(B10:C10) -> 2 | F10: 2 | G10: =SUM(E10:F10) -> 2 | H10: 2 | K10: =SUM(H10:J10) -> 2 | L10: =SUM(B10:C10) -> 2 | M10: 2 | O10: =SUM(M10:N10) -> 2 | P10: 2 | R10: =SUM(P10:Q10) -> 2 | U10: 2 | V10: =SUM(S10:U10) -> 2 | W10: =SUM(M10:N10) -> 2 | X10: =L10+W10 -> 4
A11: Agosto | D11: =SUM(B11:C11) -> 0 | G11: =SUM(E11:F11) -> 0 | K11: =SUM(H11:J11) -> 0 | L11: =SUM(B11:C11) -> 0 | N11: 7 | O11: =SUM(M11:N11) -> 7 | P11: 7 | R11: =SUM(P11:Q11) -> 7 | S11: 7 | V11: =SUM(S11:U11) -> 7 | W11: =SUM(M11:N11) -> 7 | X11: =L11+W11 -> 7
A12: Septiembre | C12: 8 | D12: =SUM(B12:C12) -> 8 | E12: 8 | G12: =SUM(E12:F12) -> 8 | J12: 8 | K12: =SUM(H12:J12) -> 8 | L12: =SUM(B12:C12) -> 8 | N12: 2 | O12: =SUM(M12:N12) -> 2 | P12: 2 | R12: =SUM(P12:Q12) -> 2 | S12: 1 | T12: 1 | V12: =SUM(S12:U12) -> 2 | W12: =SUM(M12:N12) -> 2 | X12: =L12+W12 -> 10
A13: Octubre | C13: 1 | D13: =SUM(B13:C13) -> 1 | E13: 1 | G13: =SUM(E13:F13) -> 1 | H13: 1 | K13: =SUM(H13:J13) -> 1 | L13: =SUM(B13:C13) -> 1 | O13: =SUM(M13:N13) -> 0 | R13: =SUM(P13:Q13) -> 0 | V13: =SUM(S13:U13) -> 0 | W13: =SUM(M13:N13) -> 0 | X13: =L13+W13 -> 1
A14: Noviembre | D14: =SUM(B14:C14) -> 0 | G14: =SUM(E14:F14) -> 0 | K14: =SUM(H14:J14) -> 0 | L14: =SUM(B14:C14) -> 0 | O14: =SUM(M14:N14) -> 0 | R14: =SUM(P14:Q14) -> 0 | V14: =SUM(S14:U14) -> 0 | W14: =SUM(M14:N14) -> 0 | X14: =L14+W14 -> 0
A15: Diciembre | D15: =SUM(B15:C15) -> 0 | G15: =SUM(E15:F15) -> 0 | K15: =SUM(H15:J15) -> 0 | L15: =SUM(B15:C15) -> 0 | N15: 12 | O15: =SUM(M15:N15) -> 12 | P15: 12 | R15: =SUM(P15:Q15) -> 12 | S15: 12 | V15: =SUM(S15:U15) -> 12 | W15: =SUM(M15:N15) -> 12 | X15: =L15+W15 -> 12
A16: Total por categoría | B16: =SUM(B4:B15) -> 4 | C16: =SUM(C4:C15) -> 51 | D16: =SUM(D4:D15) -> 55 | E16: =SUM(E4:E15) -> 51 | F16: =SUM(F6:F15) -> 4 | G16: =SUM(G4:G15) -> 55 | H16: =SUM(H6:H15) -> 4 | J16: =SUM(J4:J15) -> 51 | K16: =SUM(K4:K15) -> 55 | L16: =SUM(L4:L15) -> 55 | M16: =SUM(M4:M15) -> 4 | N16: =SUM(N4:N15) -> 38 | O16: =SUM(O4:O15) -> 42 | P16: =SUM(P4:P15) -> 42 | R16: =SUM(R4:R15) -> 42 | S16: =SUM(S4:S15) -> 22 | T16: =SUM(T4:T15) -> 2 | U16: =SUM(U8:U15) -> 18 | V16: =SUM(V4:V15) -> 42 | W16: =SUM(W4:W15) -> 42 | X16: =SUM(X4:X15) -> 97
A20: Resumen por año | B20: Tipo de movilidad | D20: Nivel | F20: Categoría | H20: Tipo de Actividad | K20: Modalidad
B21: Movilidad Entrante | C21: Movilidad Saliente | D21: Grado | E21: Postgrado | F21: Estudiantes | G21: Académicos | H21: Intercambio Académico | I21: Asistencia a Reuniones | J21: Cursos de Formación | K21: Virtual | L21: Presencial
B22: =L16 -> 55 | C22: =W16 -> 42 | D22: =E9+E12+E13+P4+P5+P6+P8+P9+P10+P11+P12+P15+E6 -> 93 | E22: =F10+Q6+F6 -> 4 | F22: =C16+N16 -> 89 | G22: =B16+M16 -> 8 | H22: =H6+H10+H13+S4+S5+S11+S12+S15 -> 26 | I22: =T4+T12 -> 2 | J22: =J6+J9+J12+U8+U9+U10 -> 69 | K22: 57 | L22: 40
A23: Total | B23: =B22+C22 -> 97

Sheet Movilidad FICT 2022
B1: Mes | D1: Enero | E1: Febrero | F1: Marzo | G1: Abril | H1: Mayo | I1: Junio | J1: Julio | K1: Agosto | L1: Septiembre | M1: Octubre | N1: Noviembre | O1: Diciembre | P1: Total por categoría
A2: Movilidad Entrante | B2: Categoría | C2: Académico Entrante | E2: 1 | H2: 5 | O2: 1 | P2: =SUM(D2:O2) -> 7 | R2: Resumen 2022 | U2: Total
C3: Estudiante Entrante | P3: =SUM(D3:O3) -> 0 | R3: Tipo de movilidad | S3: Movilidad Entrante | T3: =P28 -> 7 | U3: =SUM(T22:T26) -> 14
C4: Administrativo Entrante | P4: =SUM(D4:O4) -> 0 | S4: Movilidad Saliente | T4: =P54 -> 7
B5: Total Categoría | D5: =SUM(D2:D4) -> 0 | E5: =SUM(E2:E4) -> 1 | F5: =SUM(F2:F4) -> 0 | G5: =SUM(G2:G4) -> 0 | H5: =SUM(H2:H4) -> 5 | I5: =SUM(I2:I4) -> 0 | J5: =SUM(J2:J4) -> 0 | K5: =SUM(K2:K4) -> 0 | ... O5: =SUM(O2:O4) -> 1 | P5: =SUM(D5:O5) -> 7 | R5: Nivel | S5: Grado | T5: =P33+P6 -> 11
B6: Nivel | C6: Grado | H6: 5 | P6: =SUM(D6:O6) -> 5 | S6: Postgrado | T6: =P34+P7 -> 1
C7: Postgrado | P7: =SUM(D7:O7) -> 0 | R7: Categoría | S7: Estudiantes | T7: =P30+P3 -> 1
B8: Total Nivel | D8: =SUM(D6:D7) -> 0 | E8: =SUM(E6:E7) -> 0 | F8: =SUM(F6:F7) -> 0 | G8: =SUM(G6:G7) -> 0 | H8: =SUM(H6:H7) -> 5 | I8: =SUM(I6:I7) -> 0 | J8: =SUM(J6:J7) -> 0 | K8: =SUM(K6:K7) -> 0 | ... O8: =SUM(O6:O7) -> 0 | P8: =SUM(D8:O8) -> 5 | S8: Académicos | T8: =P2+P29 -> 12
B9: Carreras y Programas | C9: Civil | P9: =SUM(D9:O9) -> 0 | S9: Administrativos | T9: =P4+P31 -> 1
C10: Geología | P10: =SUM(D10:O10) -> 0 | R10: Carreras y Programas | S10: Civil | T10: =P36+P9 -> 4
C11: Minas | P11: =SUM(D11:O11) -> 0 | S11: Geología | T11: =P37+P10 -> 1
C12: Petróleos | P12: =SUM(D12:O12) -> 0 | S12: Minas | T12: =P38+P11 -> 0
C13: Con-San | P13: =SUM(D13:O13) -> 0 | S13: Petróleos | T13: =P39+P12 -> 1
C14: Est-Sis | P14: =SUM(D14:O14) -> 0 | S14: Con-San | T14: =P40+P13 -> 1
C15: GeoT | P15: =SUM(D15:O15) -> 0 | S15: Est-Sis | T15: =P41+P14 -> 0
C16: MSc | P16: =SUM(D16:O16) -> 0 | S16: GeoT | T16: =P42+P15 -> 0
C17: GeoM | P17: =SUM(D17:O17) -> 0 | S17: MSc | T17: =P43+P16 -> 0
C18: MM | P18: =SUM(D18:O18) -> 0 | S18: GeoM | T18: =P44+P17 -> 0
C19: PP | P19: =SUM(D19:O19) -> 0 | S19: MM | T19: =P45+P18 -> 0
C20: Proyecto CCUS | E20: 1 | H20: 5 | O20: 1 | P20: =SUM(D20:O20) -> 7 | S20: Proyecto CCUS | T20: =P20 -> 7
B21: Total Carreras y Programas | D21: =SUM(D9:D20) -> 0 | E21: =SUM(E9:E20) -> 1 | F21: =SUM(F9:F20) -> 0 | G21: =SUM(G9:G20) -> 0 | H21: =SUM(H9:H20) -> 5 | I21: =SUM(I9:I20) -> 0 | J21: =SUM(J9:J20) -> 0 | K21: =SUM(K9:K20) -> 0 | ... O21: =SUM(O9:O20) -> 1 | P21: =SUM(D21:O21) -> 7 | S21: PP | T21: =P46+P19 -> 0
B22: Tipo de Actividad | C22: Intercambio Académico | P22: =SUM(F22:O22) -> 0 | R22: Tipo de Actividad | S22: Intercambio Académico | T22: =P48+P22 -> 0
C23: Asistencia a Eventos | H23: 5 | P23: =SUM(F23:O23) -> 5 | S23: Asistencia a Eventos | T23: =P49+P23 -> 8
C24: Cursos de Formación | E24: 1 | O24: 1 | P24: =SUM(D24:O24) -> 2 | S24: Cursos de Formación | T24: =P50+P24 -> 5
C25: Estancia | P25: =SUM(D25:O25) -> 0 | S25: Estancia | T25: =P51 -> 1
C26: Presentación de trabajos | P26: =SUM(D26:O26) -> 0 | S26: Presentación de trabajos | T26: =P52 -> 0
B27: Total Tipo de Actividad | D27: =SUM(D22:D26) -> 0 | E27: =SUM(E22:E26) -> 1 | F27: =SUM(F22:F26) -> 0 | G27: =SUM(G22:G26) -> 0 | H27: =SUM(H22:H26) -> 5 | I27: =SUM(I22:I26) -> 0 | J27: =SUM(J22:J26) -> 0 | K27: =SUM(K22:K26) -> 0 | ... O27: =SUM(O22:O26) -> 1 | P27: =SUM(D27:O27) -> 7 | R27: Modalidad | S27: Virtual | T27: 2
B28: Total Movilidad Entrante | D28: =D27 -> 0 | E28: =E27 -> 1 | F28: =F27 -> 0 | G28: =G27 -> 0 | H28: =H27 -> 5 | I28: =I27 -> 0 | J28: =J27 -> 0 | K28: =K27 -> 0 | ... O28: =O27 -> 1 | P28: =SUM(D28:O28) -> 7 | S28: Presencial | T28: 12
A29: Movilidad Saliente | B29: Categoría | C29: Académico Saliente | D29: 2 | J29: 1 | N29: 2 | P29: =SUM(D29:O29) -> 5
C30: Estudiante Saliente | G30: 1 | P30: =SUM(D30:O30) -> 1
C31: Administrativo Saliente | N31: 1 | P31: =SUM(D31:O31) -> 1
B32: Total Categoría | D32: =SUM(D29:D31) -> 2 | E32: =SUM(E29:E31) -> 0 | F32: =SUM(F29:F31) -> 0 | G32: =SUM(G29:G31) -> 1 | H32: =SUM(H29:H31) -> 0 | I32: =SUM(I29:I31) -> 0 | J32: =SUM(J29:J31) -> 1 | K32: =SUM(K29:K31) -> 0 | ... O32: =SUM(O29:O31) -> 0 | P32: =SUM(D32:O32) -> 7
B33: Nivel | C33: Grado | D33: 2 | G33: 1 | J33: 1 | N33: 2 | P33: =SUM(D33:O33) -> 6
C34: Postgrado | N34: 1 | P34: =SUM(D34:O34) -> 1
B35: Total Nivel | P35: =SUM(D35:O35) -> 0
B36: Carreras y Programas | C36: Civil | D36: 2 | N36: 2 | P36: =SUM(D36:O36) -> 4
C37: Geología | G37: 1 | P37: =SUM(D37:O37) -> 1
C38: Minas | P38: =SUM(D38:O38) -> 0
C39: Petróleos | J39: 1 | P39: =SUM(D39:O39) -> 1
C40: Con-San | N40: 1 | P40: =SUM(D40:O40) -> 1
...

Sheet Países 2022
B1: Entrante | F1: Saliente
B2: Country | C2: Modality | D2: Count | F2: Country | G2: Modality | H2: Count
B3: Colombia | C3: In person | D3: 3 | F3: Colombia | G3: in person | H3: 7
B4: Colombia | C4: Virtual | D4: 2
B5: Norway | C5: In person | D5: 2
B6: Total | D6: =SUM(D3:D5) -> 7
F7: Total | H7: =SUM(H3:H6) -> 7

Sheet Movilidad FICT 2023
B1: Mes | D1: Enero | E1: Febrero | F1: Marzo | G1: Abril | H1: Mayo | I1: Junio | J1: Julio | K1: Agosto | L1: Septiembre | M1: Octubre | N1: Noviembre | O1: Diciembre | P1: Total por categoría
A2: Movilidad Entrante | B2: Categoría | C2: Académico Entrante | F2: 2 | I2: 2 | P2: =SUM(D2:O2) -> 4 | R2: Resumen por año (2023) | U2: Total
C3: Estudiante Entrante | F3: 1 | I3: 39 | J3: 2 | L3: 8 | M3: 1 | P3: =SUM(D3:O3) -> 51 | R3: Tipo de movilidad | S3: Movilidad Entrante | T3: =P27 -> 55 | U3: =T3+T4 -> 97
C4: Administrativo Entrante | P4: =SUM(D4:O4) -> 0 | S4: Movilidad Saliente | T4: =P53 -> 42
B5: Total Categoría | D5: =SUM(D2:D3) -> 0 | E5: =SUM(E2:E3) -> 0 | F5: =SUM(F2:F3) -> 3 | G5: =SUM(G2:G3) -> 0 | H5: =SUM(H2:H3) -> 0 | I5: =SUM(I2:I3) -> 41 | J5: =SUM(J2:J3) -> 2 | K5: =SUM(K2:K3) -> 0 | ... O5: =SUM(O2:O3) -> 0 | P5: =SUM(D5:O5) -> 55 | R5: Nivel | S5: Grado | T5: =P32+P6 -> 93
B6: Nivel | C6: Grado | F6: 1 | I6: 41 | L6: 8 | M6: 1 | P6: =SUM(D6:O6) -> 51 | S6: Postgrado | T6: =P33+P7 -> 4
C7: Postgrado | F7: 2 | J7: 2 | P7: =SUM(F7:O7) -> 4 | R7: Categoría | S7: Estudiantes | T7: =P29+P3 -> 89
B8: Total Nivel | D8: =SUM(D6:D7) -> 0 | E8: =SUM(E6:E7) -> 0 | F8: =SUM(F6:F7) -> 3 | G8: =SUM(G6:G7) -> 0 | H8: =SUM(H6:H7) -> 0 | I8: =SUM(I6:I7) -> 41 | J8: =SUM(J6:J7) -> 2 | K8: =SUM(K6:K7) -> 0 | ... O8: =SUM(O6:O7) -> 0 | P8: =SUM(D8:O8) -> 55 | S8: Académicos | T8: =P2+P28 -> 8
B9: Carreras y Programas | C9: Civil | I9: 29 | L9: 8 | M9: 1 | P9: =SUM(D9:O9) -> 38 | S9: Administrativos | T9: 0
C10: Geología | I10: 12 | P10: =SUM(D10:O10) -> 12 | R10: Carreras y Programas | S10: Civil | T10: =P35+P9 -> 75
C11: Minas | P11: =SUM(D11:O11) -> 0 | S11: Geología | T11: =P36+P10 -> 12
C12: Petróleos | F12: 1 | P12: =SUM(D12:O12) -> 1 | S12: Minas | T12: =P37+P11 -> 1
C13: Con-San | P13: =SUM(D13:O13) -> 0 | S13: Petróleos | T13: =P38+P12 -> 5
C14: Est-Sis | P14: =SUM(D14:O14) -> 0 | S14: Con-San | T14: =P39+P13 -> 0
C15: GeoT | F15: 2 | I15: 2 | P15: =SUM(D15:O15) -> 4 | S15: Est-Sis | T15: =P40+P14 -> 0
C16: MSc | P16: =SUM(D16:O16) -> 0 | S16: GeoT | T16: =P41+P15 -> 4
C17: GeoM | P17: =SUM(D17:O17) -> 0 | S17: MSc | T17: =P42+P16 -> 0
C18: MM | P18: =SUM(D18:O18) -> 0 | S18: GeoM | T18: =P43+P17 -> 0
C19: PP | P19: =SUM(D19:O19) -> 0 | S19: MM | T19: =P44+P18 -> 0
B20: Total Carreras y Programas | D20: =SUM(D9:D19) -> 0 | E20: =SUM(E9:E19) -> 0 | F20: =SUM(F9:F19) -> 3 | G20: =SUM(G9:G19) -> 0 | H20: =SUM(H9:H19) -> 0 | I20: =SUM(I9:I19) -> 43 | J20: =SUM(J9:J19) -> 0 | K20: =SUM(K9:K19) -> 0 | ... O20: =SUM(O9:O19) -> 0 | P20: =SUM(D20:O20) -> 55 | S20: PP | T20: =P45+P19 -> 0
B21: Tipo de Actividad | C21: Intercambio Académico | F21: 1 | J21: 2 | M21: 1 | P21: =SUM(F21:O21) -> 4 | R21: Tipo de Actividad | S21: Intercambio Académico | T21: =P47+P21 -> 26
C22: Asistencia a Eventos | P22: =SUM(F22:O22) -> 0 | S22: Asistencia a Eventos | T22: =P48+P22 -> 2
C23: Cursos de Formación | F23: 2 | I23: 41 | L23: 8 | P23: =SUM(D23:O23) -> 51 | S23: Cursos de Formación | T23: =P49+P23 -> 69
C24: Estancia | P24: =SUM(D24:O24) -> 0 | S24: Estancia | T24: =P50+P24 -> 0
C25: Presentación de Trabajos | P25: =SUM(D25:O25) -> 0 | S25: Presentación de Trabajos | T25: =P51+P25 -> 0
B26: Total Tipo de Actividad | D26: =SUM(D21:D23) -> 0 | E26: =SUM(E21:E23) -> 0 | F26: =SUM(F21:F23) -> 3 | G26: =SUM(G21:G23) -> 0 | H26: =SUM(H21:H23) -> 0 | I26: =SUM(I21:I23) -> 41 | J26: =SUM(J21:J23) -> 2 | K26: =SUM(K21:K23) -> 0 | ... O26: =SUM(O21:O23) -> 0 | P26: =SUM(D26:O26) -> 55 | R26: Modalidad | S26: Virtual | T26: 57
B27: Total Movilidad Entrante | D27: =D5+D8+D26 -> 0 | E27: =SUM(E2:E3) -> 0 | F27: =SUM(F2:F3) -> 3 | G27: =SUM(G2:G3) -> 0 | H27: =SUM(H2:H3) -> 0 | I27: =SUM(I2:I3) -> 41 | J27: =SUM(J2:J3) -> 2 | K27: =SUM(K2:K3) -> 0 | L27: =SUM(L2:L3) -> 8 | ... O27: =SUM(O2:O3) -> 0 | P27: =SUM(D27:O27) -> 55 | S27: Presencial | T27: 40
A28: Movilidad Saliente | B28: Categoría | C28: Académico Saliente | D28: 1 | H28: 1 | J28: 2 | P28: =SUM(D28:O28) -> 4
C29: Estudiante Saliente | D29: 1 | E29: 1 | I29: 15 | K29: 7 | L29: 2 | O29: 12 | P29: =SUM(D29:O29) -> 38
C30: Administrativo Saliente | P30: =SUM(D30:O30) -> 0
B31: Total Categoría | D31: =SUM(D28:D29) -> 2 | E31: =SUM(E28:E29) -> 1 | F31: =SUM(F28:F29) -> 0 | G31: =SUM(G28:G29) -> 0 | H31: =SUM(H28:H29) -> 1 | I31: =SUM(I28:I29) -> 15 | J31: =SUM(J28:J29) -> 2 | K31: =SUM(K28:K29) -> 7 | ... O31: =SUM(O28:O29) -> 12 | P31: =SUM(D31:O31) -> 42
B32: Nivel | C32: Grado | D32: 2 | E32: 1 | H32: 1 | I32: 15 | J32: 2 | K32: 7 | L32: 2 | O32: 12 | P32: =SUM(D32:O32) -> 42
C33: Postgrado | P33: =SUM(D33:O33) -> 0
B34: Total Nivel | D34: =SUM(D32:D33) -> 2 | E34: =SUM(E32:E33) -> 1 | F34: =SUM(F32:F33) -> 0 | G34: =SUM(G32:G33) -> 0 | H34: =SUM(H32:H33) -> 1 | I34: =SUM(I32:I33) -> 15 | J34: =SUM(J32:J33) -> 2 | K34: =SUM(K32:K33) -> 7 | ... O34: =SUM(O32:O33) -> 12 | P34: =SUM(D34:O34) -> 42
B35: Carreras y Programas | C35: Civil | E35: 1 | I35: 15 | K35: 7 | L35: 2 | O35: 12 | P35: =SUM(D35:O35) -> 37
C36: Geología | P36: =SUM(D36:O36) -> 0
C37: Minas | D37: 1 | P37: =SUM(D37:O37) -> 1
C38: Petróleos | D38: 1 | H38: 1 | J38: 2 | P38: =SUM(D38:O38) -> 4
C39: Con-San | P39: =SUM(D39:O39) -> 0
C40: Est-Sis | P40: =SUM(D40:O40) -> 0
...

Sheet Países 2023
B1: Entrante | F1: Saliente
B2: Country | C2: Modality | D2: Count | F2: Country | G2: Modality | H2: Count
B3: Argentina | C3: Virtual | D3: 3 | F3: Guatemala | G3: in person | H3: 1
B4: Bolivia | C4: Virtual | D4: 31 | F4: United Kindgom | G4: in person | H4: 1
B5: Brasil | C5: In person | D5: 3 | F5: Uruguay | G5: in person | H5: 1
B6: Colombia | C6: In person | D6: 11 | F6: Suiza | G6: in person | H6: 1
B7: Spain | C7: In person | D7: 2 | F7: Panama | G7: in person | H7: 2
B8: United States | C8: In person | D8: 12 | F8: Spain | G8: in person | H8: 4
B9: Italy | C9: In person | D9: 2 | F9: Italy | G9: in person | H9: 4
B10: Mexico | C10: Virtual | D10: 2 | F10: Norway | G10: in person | H10: 4
B11: Norway | C11: In person | D11: 2
B12: Peru | C12: Virtual | D12: 29
B13: Total | D13: =SUM(D3:D12) -> 97 | F13: Brasil | G13: in person | H13: 8
F14: Peru | G14: Virtual | H14: 12
F15: Colombia | G15: in person | H15: 40
F16: Total | H16: =SUM(H3:H15) -> 78

Sheet Movilidad FICT 2024
B1: Mes | D1: Enero | E1: Febrero | F1: Marzo | G1: Abril | H1: Mayo | I1: Junio | J1: Julio | K1: Agosto | L1: Septiembre | M1: Octubre | N1: Noviembre | O1: Diciembre | P1: Total por categoría
A2: Movilidad Entrante | B2: Categoría | C2: Académico Entrante | D2: 2 | E2: 2 | G2: 1 | I2: 5 | K2: 2 | M2: 3 | O2: 1 | P2: =SUM(D2:O2) -> 16 | R2: Resumen 2024 | U2: Total
C3: Estudiante Entrante | G3: 15 | J3: 1 | K3: 15 | O3: 19 | P3: =SUM(D3:O3) -> 50 | R3: Tipo de movilidad | S3: Movilidad Entrante | T3: =P27 -> 66 | U3: =SUM(T21:T25) -> 144
C4: Administrativo Entrante | P4: =SUM(D4:O4) -> 0 | S4: Movilidad Saliente | T4: =P53 -> 78
B5: Total Categoría | D5: =SUM(D2:D4) -> 2 | E5: =SUM(E2:E4) -> 2 | F5: =SUM(F2:F4) -> 0 | G5: =SUM(G2:G4) -> 16 | H5: =SUM(H2:H4) -> 0 | I5: =SUM(I2:I4) -> 5 | J5: =SUM(J2:J4) -> 1 | K5: =SUM(K2:K4) -> 17 | ... O5: =SUM(O2:O4) -> 20 | P5: =SUM(D5:O5) -> 66 | R5: Nivel | S5: Grado | T5: =P32+P6 -> 111
B6: Nivel | C6: Grado | G6: 16 | I6: 3 | J6: 1 | K6: 16 | M6: 3 | O6: 19 | P6: =SUM(D6:O6) -> 58 | S6: Postgrado | T6: =P33+P7 -> 33
C7: Postgrado | D7: 2 | E7: 2 | I7: 2 | K7: 1 | O7: 1 | P7: =SUM(D7:O7) -> 8 | R7: Categoría | S7: Estudiantes | T7: =P29+P3 -> 95
B8: Total Nivel | D8: =SUM(D6:D7) -> 2 | E8: =SUM(E6:E7) -> 2 | F8: =SUM(F6:F7) -> 0 | G8: =SUM(G6:G7) -> 16 | H8: =SUM(H6:H7) -> 0 | I8: =SUM(I6:I7) -> 5 | J8: =SUM(J6:J7) -> 1 | K8: =SUM(K6:K7) -> 17 | ... O8: =SUM(O6:O7) -> 20 | P8: =SUM(D8:O8) -> 66 | S8: Académicos | T8: =P2+P28 -> 47
B9: Carreras y Programas | C9: Civil | I9: 2 | K9: 16 | P9: =SUM(D9:O9) -> 18 | S9: Administrativos | T9: =P4+P30 -> 2
C10: Geología | I10: 1 | P10: =SUM(D10:O10) -> 1 | R10: Carreras y Programas | S10: Civil | T10: =P35+P9 -> 42
C11: Minas | M11: 2 | P11: =SUM(D11:O11) -> 2 | S11: Geología | T11: =P36+P10 -> 5
C12: Petróleos | G12: 16 | J12: 1 | M12: 1 | O12: 19 | P12: =SUM(D12:O12) -> 37 | S12: Minas | T12: =P37+P11 -> 5
C13: Con-San | D13: 2 | P13: =SUM(D13:O13) -> 2 | S13: Petróleos | T13: =P38+P12 -> 59
C14: Est-Sis | P14: =SUM(D14:O14) -> 0 | S14: Con-San | T14: =P39+P13 -> 26
C15: GeoT | E15: 2 | K15: 1 | P15: =SUM(D15:O15) -> 3 | S15: Est-Sis | T15: =P40+P14 -> 1
C16: MSc | O16: 1 | P16: =SUM(D16:O16) -> 1 | S16: GeoT | T16: =P41+P15 -> 3
C17: GeoM | P17: =SUM(D17:O17) -> 0 | S17: MSc | T17: =P42+P16 -> 1
C18: MM | I18: 2 | P18: =SUM(D18:O18) -> 2 | S18: GeoM | T18: =P43+P17 -> 0
C19: PP | P19: =SUM(D19:O19) -> 0 | S19: MM | T19: =P44+P18 -> 2
B20: Total Carreras y Programas | D20: =SUM(D9:D19) -> 2 | E20: =SUM(E9:E19) -> 2 | F20: =SUM(F9:F19) -> 0 | G20: =SUM(G9:G19) -> 16 | H20: =SUM(H9:H19) -> 0 | I20: =SUM(I9:I19) -> 5 | J20: =SUM(J9:J19) -> 1 | K20: =SUM(K9:K19) -> 17 | ... O20: =SUM(O9:O19) -> 20 | P20: =SUM(D20:O20) -> 66 | S20: PP | T20: =P45+P19 -> 0
B21: Tipo de Actividad | C21: Intercambio Académico | I21: 1 | K21: 1 | P21: =SUM(F21:O21) -> 2 | R21: Tipo de Actividad | S21: Intercambio Académico | T21: =P47+P21 -> 3
C22: Asistencia a Eventos | P22: =SUM(F22:O22) -> 0 | S22: Asistencia a Eventos | T22: =P48+P22 -> 15
C23: Cursos de Formación | D23: 2 | E23: 2 | G23: 16 | I23: 4 | J23: 1 | K23: 16 | M23: 3 | O23: 20 | P23: =SUM(D23:O23) -> 64 | S23: Cursos de Formación | T23: =P49+P23 -> 92
C24: Estancia | P24: =SUM(D24:O24) -> 0 | S24: Estancia | T24: =P50 -> 29
C25: Presentación de trabajos | P25: =SUM(D25:O25) -> 0 | S25: Presentación de trabajos | T25: =P51 -> 5
B26: Total Tipo de Actividad | D26: =SUM(D21:D25) -> 2 | E26: =SUM(E21:E25) -> 2 | F26: =SUM(F21:F25) -> 0 | G26: =SUM(G21:G25) -> 16 | H26: =SUM(H21:H25) -> 0 | I26: =SUM(I21:I25) -> 5 | J26: =SUM(J21:J25) -> 1 | K26: =SUM(K21:K25) -> 17 | ... O26: =SUM(O21:O25) -> 20 | P26: =SUM(D26:O26) -> 66 | R26: Modalidad | S26: Virtual | T26: 97
B27: Total Movilidad Entrante | D27: =D26 -> 2 | E27: =E26 -> 2 | F27: =F26 -> 0 | G27: =G26 -> 16 | H27: =H26 -> 0 | I27: =I26 -> 5 | J27: =J26 -> 1 | K27: =K26 -> 17 | ... O27: =O26 -> 20 | P27: =SUM(D27:O27) -> 66 | S27: Presencial | T27: 47
A28: Movilidad Saliente | B28: Categoría | C28: Académico Saliente | D28: 2 | E28: 1 | F28: 1 | G28: 11 | H28: 3 | I28: 5 | J28: 4 | K28: 1 | L28: 1 | M28: 1 | O28: 1 | P28: =SUM(D28:O28) -> 31
C29: Estudiante Saliente | E29: 1 | G29: 2 | H29: 3 | I29: 11 | J29: 23 | M29: 5 | P29: =SUM(D29:O29) -> 45
C30: Administrativo Saliente | G30: 1 | J30: 1 | P30: =SUM(D30:O30) -> 2
B31: Total Categoría | D31: =SUM(D28:D30) -> 2 | E31: =SUM(E28:E30) -> 2 | F31: =SUM(F28:F30) -> 1 | G31: =SUM(G28:G30) -> 14 | H31: =SUM(H28:H30) -> 6 | I31: =SUM(I28:I30) -> 16 | J31: =SUM(J28:J30) -> 28 | K31: =SUM(K28:K30) -> 1 | ... O31: =SUM(O28:O30) -> 1 | P31: =SUM(D31:O31) -> 78
B32: Nivel | C32: Grado | D32: 1 | E32: 2 | F32: 1 | G32: 11 | H32: 6 | I32: 16 | J32: 7 | K32: 1 | L32: 1 | M32: 6 | O32: 1 | P32: =SUM(D32:O32) -> 53
C33: Postgrado | D33: 1 | G33: 3 | J33: 21 | P33: =SUM(D33:O33) -> 25
B34: Total Nivel | D34: =SUM(D32:D33) -> 2 | E34: =SUM(E32:E33) -> 2 | F34: =SUM(F32:F33) -> 1 | G34: =SUM(G32:G33) -> 14 | H34: =SUM(H32:H33) -> 6 | I34: =SUM(I32:I33) -> 16 | J34: =SUM(J32:J33) -> 28 | K34: =SUM(K32:K33) -> 1 | ... O34: =SUM(O32:O33) -> 1 | P34: =SUM(D34:O34) -> 78
B35: Carreras y Programas | C35: Civil | E35: 1 | F35: 1 | G35: 6 | I35: 13 | J35: 2 | M35: 1 | P35: =SUM(D35:O35) -> 24
C36: Geología | E36: 1 | G36: 1 | H36: 1 | L36: 1 | P36: =SUM(D36:O36) -> 4
C37: Minas | H37: 1 | I37: 2 | P37: =SUM(D37:O37) -> 3
C38: Petróleos | D38: 1 | G38: 4 | H38: 4 | I38: 1 | J38: 5 | K38: 1 | M38: 5 | O38: 1 | P38: =SUM(D38:O38) -> 22
C39: Con-San | D39: 1 | G39: 2 | J39: 21 | P39: =SUM(D39:O39) -> 24
C40: Est-Sis | G40: 1 | P40: =SUM(D40:O40) -> 1
...

Sheet Países 2024
B1: Entrante | F1: Saliente
B2: Country | C2: Modality | D2: Count | F2: Country | G2: Modality | H2: Count
B3: Belgium | C3: Virtual | D3: 1 | F3: Guatemala | G3: in person | H3: 1
B4: South Korea | C4: Virtual | D4: 1 | F4: United Kingdom | G4: in person | H4: 1
B5: Chile | C5: Virtual | D5: 2 | F5: Uruguay | G5: in person | H5: 1
B6: Norway | C6: In person | D6: 2 | F6: Suiza | G6: in person | H6: 1
B7: Spain | C7: In person | D7: 3 | F7: Panama | G7: in person | H7: 2
B8: Italy | C8: In person | D8: 3 | F8: Spain | G8: in person | H8: 4
B9: Peru | C9: Virtual | D9: 17 | F9: Italy | G9: in person | H9: 4
B10: Colombia | C10: Virtual | D10: 37 | F10: Norway | G10: in person | H10: 4
B11: Total | D11: =SUM(D3:D10) -> 66 | F11: Brasil | G11: in person | H11: 8
F12: Peru | G12: Virtual | H12: 12
F13: Colombia | G13: in person | H13: 40
F14: Total | H14: =SUM(H3:H13) -> 78

Sheet Movilidad +FICT 2024
B1: Movilidad Entrante | M1: Movilidad Saliente
A2: Mes | B2: Categoría | D2: Total Categoría | E2: Nivel | G2: Total Nivel | H2: Tipo de Actividad | K2: Total Tipo de Actividad | L2: Total Movilidad Entrante | M2: Categoría | O2: Total Categoría | P2: Nivel | R2: Total Nivel | S2: Tipo de Actividad | X2: Total Tipo de Actividad | Y2: Total Movilidad Saliente | Z2: Total por mes
B3: Académico Entrante | C3: Estudiante Entrante | E3: Grado | F3: Postgrado | H3: Intercambio Académico | I3: Asistencia a Eventos | J3: Cursos de Formación | M3: Académico Saliente | N3: Estudiante Saliente | P3: Grado | Q3: Postgrado | S3: Intercambio Académico | T3: Asitencia a Eventos | U3: Cursos de Formación | V3: Estancia | W3: Presentación de Trabajos en Eventos
A4: Enero | D4: =SUM(B4:C4) -> 0 | G4: =SUM(E4:F4) -> 0 | K4: =SUM(H4:J4) -> 0 | L4: =D4+G4+K4 -> 0 | O4: =SUM(M4:N4) -> 0 | R4: =SUM(P4:Q4) -> 0 | X4: =SUM(S4:W4) -> 0 | Y4: =SUM(M4:N4) -> 0 | Z4: =L4+Y4 -> 0
A5: Febrero | D5: =SUM(B5:C5) -> 0 | G5: =SUM(E5:F5) -> 0 | K5: =SUM(H5:J5) -> 0 | L5: =SUM(B5:C5) -> 0 | M5: 9 | N5: 3 | O5: =SUM(M5:N5) -> 12 | P5: 12 | R5: =SUM(P5:Q5) -> 12 | S5: 3 | U5: 4 | V5: 5 | X5: =SUM(S5:W5) -> 12 | Y5: =SUM(M5:N5) -> 12 | Z5: =L5+Y5 -> 12
A6: Marzo | D6: =SUM(B6:C6) -> 0 | G6: =SUM(E6:F6) -> 0 | K6: =SUM(H6:J6) -> 0 | L6: =SUM(B6:C6) -> 0 | M6: 1 | O6: =SUM(M6:N6) -> 1 | P6: 1 | R6: =SUM(P6:Q6) -> 1 | V6: 1 | X6: =SUM(S6:W6) -> 1 | Y6: =SUM(M6:N6) -> 1 | Z6: =L6+Y6 -> 1
A7: Abril | B7: 2 | D7: =SUM(B7:C7) -> 2 | F7: 2 | G7: =SUM(E7:F7) -> 2 | J7: 2 | K7: =SUM(H7:J7) -> 2 | L7: =SUM(B7:C7) -> 2 | M7: 7 | N7: 5 | O7: =SUM(M7:N7) -> 12 | P7: 11 | Q7: 1 | R7: =SUM(P7:Q7) -> 12 | T7: 6 | U7: 1 | V7: 3 | W7: 2 | X7: =SUM(S7:W7) -> 12 | Y7: =SUM(M7:N7) -> 12 | Z7: =L7+Y7 -> 14
A8: Mayo | C8: 16 | D8: =SUM(B8:C8) -> 16 | E8: 16 | G8: =SUM(E8:F8) -> 16 | J8: 16 | K8: =SUM(H8:J8) -> 16 | L8: =SUM(B8:C8) -> 16 | M8: 2 | N8: 3 | O8: =SUM(M8:N8) -> 5 | P8: 5 | R8: =SUM(P8:Q8) -> 5 | T8: 5 | X8: =SUM(S8:W8) -> 5 | Y8: =SUM(M8:N8) -> 5 | Z8: =L8+Y8 -> 21
A9: Junio | D9: =SUM(B9:C9) -> 0 | G9: =SUM(E9:F9) -> 0 | K9: =SUM(H9:J9) -> 0 | L9: =SUM(B9:C9) -> 0 | O9: =SUM(M9:N9) -> 0 | R9: =SUM(P9:Q9) -> 0 | X9: =SUM(S9:W9) -> 0 | Y9: =SUM(M9:N9) -> 0 | Z9: =L9+Y9 -> 0
A10: Julio | D10: =SUM(B10:C10) -> 0 | G10: =SUM(E10:F10) -> 0 | K10: =SUM(H10:J10) -> 0 | L10: =SUM(B10:C10) -> 0 | O10: =SUM(M10:N10) -> 0 | R10: =SUM(P10:Q10) -> 0 | X10: =SUM(S10:W10) -> 0 | Y10: =SUM(M10:N10) -> 0 | Z10: =L10+Y10 -> 0
A11: Agosto | D11: =SUM(B11:C11) -> 0 | G11: =SUM(E11:F11) -> 0 | K11: =SUM(H11:J11) -> 0 | L11: =SUM(B11:C11) -> 0 | O11: =SUM(M11:N11) -> 0 | R11: =SUM(P11:Q11) -> 0 | X11: =SUM(S11:W11) -> 0 | Y11: =SUM(M11:N11) -> 0 | Z11: =L11+Y11 -> 0
A12: Septiembre | D12: =SUM(B12:C12) -> 0 | G12: =SUM(E12:F12) -> 0 | K12: =SUM(H12:J12) -> 0 | L12: =SUM(B12:C12) -> 0 | O12: =SUM(M12:N12) -> 0 | R12: =SUM(P12:Q12) -> 0 | X12: =SUM(S12:W12) -> 0 | Y12: =SUM(M12:N12) -> 0 | Z12: =L12+Y12 -> 0
A13: Octubre | D13: =SUM(B13:C13) -> 0 | G13: =SUM(E13:F13) -> 0 | K13: =SUM(H13:J13) -> 0 | L13: =SUM(B13:C13) -> 0 | O13: =SUM(M13:N13) -> 0 | R13: =SUM(P13:Q13) -> 0 | X13: =SUM(S13:W13) -> 0 | Y13: =SUM(M13:N13) -> 0 | Z13: =L13+Y13 -> 0
A14: Noviembre | D14: =SUM(B14:C14) -> 0 | G14: =SUM(E14:F14) -> 0 | K14: =SUM(H14:J14) -> 0 | L14: =SUM(B14:C14) -> 0 | O14: =SUM(M14:N14) -> 0 | R14: =SUM(P14:Q14) -> 0 | X14: =SUM(S14:W14) -> 0 | Y14: =SUM(M14:N14) -> 0 | Z14: =L14+Y14 -> 0
A15: Diciembre | D15: =SUM(B15:C15) -> 0 | G15: =SUM(E15:F15) -> 0 | K15: =SUM(H15:J15) -> 0 | L15: =SUM(B15:C15) -> 0 | O15: =SUM(M15:N15) -> 0 | R15: =SUM(P15:Q15) -> 0 | X15: =SUM(S15:W15) -> 0 | Y15: =SUM(M15:N15) -> 0 | Z15: =L15+Y15 -> 0
A16: Total por categoría | B16: =SUM(B4:B15) -> 2 | C16: =SUM(C4:C15) -> 16 | D16: =SUM(D4:D15) -> 18 | E16: =SUM(E4:E15) -> 16 | F16: =SUM(F6:F15) -> 2 | G16: =SUM(G4:G15) -> 18 | H16: =SUM(H4:H15) -> 0 | I16: =SUM(I4:I15) -> 0 | J16: =SUM(J4:J15) -> 18 | K16: =SUM(K4:K15) -> 18 | L16: =SUM(L4:L15) -> 18 | M16: =SUM(M4:M15) -> 19 | N16: =SUM(N4:N15) -> 11 | ... P16: =SUM(P4:P15) -> 29 | Q16: =SUM(Q5:Q15) -> 1 | R16: =SUM(R4:R15) -> 30 | S16: =SUM(S4:S15) -> 3 | T16: =SUM(T4:T15) -> 11 | U16: =SUM(U4:U15) -> 5 | V16: =SUM(V4:V15) -> 9 | W16: =SUM(W4:W15) -> 2 | X16: =SUM(X4:X15) -> 30 | Y16: =SUM(Y4:Y15) -> 30 | Z16: =SUM(Z4:Z15) -> 48
A20: Resumen por año | B20: Tipo de movilidad | D20: Nivel | F20: Categoría | H20: Tipo de Actividad | M20: Modalidad
B21: Movilidad Entrante | C21: Movilidad Saliente | D21: Grado | E21: Postgrado | F21: Estudiantes | G21: Académicos | H21: Intercambio Académico | I21: Asistencia a Eventos | J21: Cursos de Formación | K21: Estancia | L21: Presentación de Trabajos en Eventos | M21: Virtual | N21: Presencial
B22: =L16 -> 18 | C22: =Y16 -> 30 | D22: =E16+P16 -> 45 | E22: =F16+Q16 -> 3 | F22: =C16+N16 -> 27 | G22: =B16+M16 -> 21 | H22: =H16+S16 -> 3 | I22: =I16+T16 -> 11 | J22: =J16+U16 -> 23 | K22: =V16 -> 9 | L22: =W16 -> 2 | M22: 27 | N22: 21
A23: Total | B23: =B22+C22 -> 48

Sheet Movilidad FICT 2024.
A2: Mes | B2: Movilidad Entrante | D2: Total Entrante | E2: Movilidad Saliente | G2: Total Saliente | H2: Total por mes
B3: Académico Entrante | C3: Estudiante Entrante | E3: Académico Saliente | F3: Estudiante Saliente
A4: Enero | D4: =SUM(B4:C4) -> 0 | G4: =SUM(E4:F4) -> 0 | H4: =D4+G4 -> 0
A5: Febrero | D5: =SUM(B5:C5) -> 0 | G5: =SUM(E5:F5) -> 0 | H5: =D5+G5 -> 0
A6: Marzo | D6: =SUM(B6:C6) -> 0 | G6: =SUM(E6:F6) -> 0 | H6: =D6+G6 -> 0
A7: Abril | B7: 2 | D7: =SUM(B7:C7) -> 2 | E7: 2 | F7: 2 | G7: =SUM(E7:F7) -> 4 | H7: =D7+G7 -> 6
A8: Mayo | C8: 16 | D8: =SUM(B8:C8) -> 16 | E8: 17 | F8: 9 | G8: =SUM(E8:F8) -> 26 | H8: =D8+G8 -> 42
A9: Junio | D9: =SUM(B9:C9) -> 0 | G9: =SUM(E9:F9) -> 0 | H9: =D9+G9 -> 0
A10: Julio | D10: =SUM(B10:C10) -> 0 | G10: =SUM(E10:F10) -> 0 | H10: =D10+G10 -> 0
A11: Agosto | D11: =SUM(B11:C11) -> 0 | G11: =SUM(E11:F11) -> 0 | H11: =D11+G11 -> 0
A12: Septiembre | D12: =SUM(B12:C12) -> 0 | G12: =SUM(E12:F12) -> 0 | H12: =D12+G12 -> 0
A13: Octubre | D13: =SUM(B13:C13) -> 0 | G13: =SUM(E13:F13) -> 0 | H13: =D13+G13 -> 0
A14: Noviembre | D14: =SUM(B14:C14) -> 0 | G14: =SUM(E14:F14) -> 0 | H14: =D14+G14 -> 0
A15: Diciembre | D15: =SUM(B15:C15) -> 0 | G15: =SUM(E15:F15) -> 0 | H15: =D15+G15 -> 0
A16: Total por categoría | B16: =SUM(B4:B15) -> 2 | C16: =SUM(C4:C15) -> 16 | D16: =SUM(D4:D15) -> 18 | E16: =SUM(E4:E15) -> 19 | F16: =SUM(F4:F15) -> 11 | G16: =SUM(G4:G15) -> 30 | H16: =SUM(H4:H15) -> 48
A20: Resumen a la fecha actual (29/05/2024) | B20: Tipo de movilidad | D20: Categoría | F20: Modalidad
B21: Movilidad Entrante | C21: Movilidad Saliente | D21: Estudiantes | E21: Académicos | F21: Virtual | G21: Presencial
B22: 18 | C22: 30 | D22: =C16+F16 -> 27 | E22: =B16+E16 -> 21 | F22: 27 | G22: 21
A23: Total | B23: =B22+C22 -> 48

Sheet Movilidades Países 2023
A2: Países | B2: Paises | C2: Argentina | D2: Brasil | E2: Chile | F2: Colombia | G2: Estados Unidos | H2: España | I2: Italia | J2: Noruega | K2: Perú | L2: Rusia | M2: Total Tipo Movilidad
A3: Tipo de Movilidad | B3: Entrante | C3: 1 | D3: 1 | F3: 8 | G3: 12 | H3: 2 | I3: 2 | K3: 30 | M3: =SUM(C3:L3) -> 56
B4: Saliente | C4: 2 | D4: 1 | E4: 1 | F4: 20 | H4: 1 | J4: 1 | K4: 15 | L4: 1 | M4: =SUM(C4:L4) -> 42
A5: Total País | C5: =SUM(C3:C4) -> 3 | D5: =SUM(D3:D4) -> 2 | E5: =SUM(E3:E4) -> 1 | F5: =SUM(F3:F4) -> 28 | G5: =SUM(G3:G4) -> 12 | H5: =SUM(H3:H4) -> 3 | I5: =SUM(I3:I4) -> 2 | J5: =SUM(J3:J4) -> 1 | ... M5: =SUM(M3:M4) -> 98
A6: Mes | B6: Enero | D6: 1 | J6: 1 | M6: =SUM(C6:L6) -> 2
B7: Febrero | F7: 1 | M7: =SUM(C7:L7) -> 1
B8: Marzo | C8: 1 | H8: 2 | M8: =SUM(C8:L8) -> 3
B9: Abril | M9: =SUM(C9:L9) -> 0
B10: Mayo | L10: 1 | M10: =SUM(C10:L10) -> 1
B11: Junio | G11: 12 | K11: 44 | M11: =SUM(C11:L11) -> 56
B12: Julio | C12: 2 | I12: 2 | M12: =SUM(C12:L12) -> 4
B13: Agosto | D13: 1 | F13: 7 | M13: =SUM(C13:L13) -> 8
B14: Septiembre | D14: 1 | F14: 8 | H14: 1 | M14: =SUM(C14:L14) -> 10
B15: Octubre | K15: 1 | M15: =SUM(C15:L15) -> 1
B16: Noviembre | M16: =SUM(C16:L16) -> 0
B17: Diciembre | F17: 12 | M17: =SUM(C17:L17) -> 12
A18: Total Mes | C18: =SUM(C6:C17) -> 3 | D18: =SUM(D6:D17) -> 3 | E18: =SUM(E6:E17) -> 0 | F18: =SUM(F6:F17) -> 28 | G18: =SUM(G6:G17) -> 12 | H18: =SUM(H6:H17) -> 3 | I18: =SUM(I6:I17) -> 2 | J18: =SUM(J6:J17) -> 1 | ... M18: =SUM(M6:M17) -> 98

Sheet Movilidades Países 2024
A2: Países | B2: Paises | C2: Brasil | D2: Colombia | E2: España | F2: Italia | G2: Francia | H2: Noruega | I2: Reino Unido | J2: Total Tipo Movilidad
A3: Tipo de Movilidad | B3: Entrante | D3: 16 | F3: 2 | J3: =SUM(C3:I3) -> 18
B4: Saliente | C4: 12 | D4: 3 | E4: 6 | F4: 1 | G4: 1 | H4: 2 | I4: 1 | J4: =SUM(C4:I4) -> 26
A5: Total País | C5: =SUM(C3:C4) -> 12 | D5: =SUM(D3:D4) -> 19 | E5: =SUM(E3:E4) -> 6 | F5: =SUM(F3:F4) -> 3 | G5: =SUM(G3:G4) -> 1 | H5: =SUM(H3:H4) -> 2 | I5: =SUM(I3:I4) -> 1 | J5: =SUM(J3:J4) -> 44
A6: Mes | B6: Enero | J6: =SUM(C6:I6) -> 0
B7: Febrero | C7: 4 | E7: 2 | F7: 1 | G7: 1 | J7: =SUM(C7:I7) -> 8
B8: Marzo | C8: 1 | J8: =SUM(C8:I8) -> 1
B9: Abril | C9: 3 | D9: 3 | E9: 4 | F9: 2 | H9: 2 | J9: =SUM(C9:I9) -> 14
B10: Mayo | C10: 4 | D10: 16 | I10: 1 | J10: =SUM(C10:I10) -> 21
B11: Junio | J11: =SUM(C11:I11) -> 0
B12: Julio | J12: =SUM(C12:I12) -> 0
B13: Agosto | J13: =SUM(C13:I13) -> 0
B14: Septiembre | J14: =SUM(C14:I14) -> 0
B15: Octubre | J15: =SUM(C15:I15) -> 0
B16: Noviembre | J16: =SUM(C16:I16) -> 0
B17: Diciembre | J17: =SUM(C17:I17) -> 0
A18: Total Mes | C18: =SUM(C6:C17) -> 12 | D18: =SUM(D6:D17) -> 19 | E18: =SUM(E6:E17) -> 6 | F18: =SUM(F6:F17) -> 3 | G18: =SUM(G6:G17) -> 1 | H18: =SUM(H6:H17) -> 2 | I18: =SUM(I6:I17) -> 1 | J18: =SUM(J6:J17) -> 44

Sheet Movilidad FICT 2025
B1: Mes | D1: Enero | E1: Febrero | F1: Marzo | G1: Abril | H1: Mayo | I1: Junio | J1: Julio | K1: Agosto | L1: Septiembre | M1: Octubre | N1: Noviembre | O1: Diciembre | P1: Total por categoría
A2: Movilidad Entrante | B2: Categoría | C2: Académico Entrante | D2: 1 | E2: 1 | G2: 3 | H2: 2 | I2: 1 | J2: 5 | K2: 11 | L2: 6 | M2: 1 | N2: 3 | O2: 9 | P2: =SUM(D2:O2) -> 43 | R2: Resumen 2025 | U2: Total
C3: Estudiante Entrante | H3: 12 | I3: 1 | J3: 4 | N3: 41 | O3: 8 | P3: =SUM(D3:O3) -> 66 | R3: Tipo de movilidad | S3: Movilidad Entrante | T3: =P27 -> 109 | U3: =SUM(T21:T25) -> 286
C4: Administrativo Entrante | P4: =SUM(D4:O4) -> 0 | S4: Movilidad Saliente | T4: =P53 -> 177
B5: Total Categoría | D5: =SUM(D2:D4) -> 1 | E5: =SUM(E2:E4) -> 1 | F5: =SUM(F2:F4) -> 0 | G5: =SUM(G2:G4) -> 3 | H5: =SUM(H2:H4) -> 14 | I5: =SUM(I2:I4) -> 2 | J5: =SUM(J2:J4) -> 9 | K5: =SUM(K2:K4) -> 11 | ... O5: =SUM(O2:O4) -> 17 | P5: =SUM(D5:O5) -> 109 | R5: Nivel | S5: Grado | T5: =P32+P6 -> 238
B6: Nivel | C6: Grado | D6: 1 | E6: 1 | G6: 1 | H6: 13 | I6: 1 | J6: 5 | K6: 9 | N6: 44 | O6: 17 | P6: =SUM(D6:O6) -> 92 | S6: Postgrado | T6: =P33+P7 -> 48
C7: Postgrado | G7: 2 | H7: 1 | I7: 1 | J7: 4 | K7: 2 | L7: 6 | M7: 1 | P7: =SUM(D7:O7) -> 17 | R7: Categoría | S7: Estudiantes | T7: =P29+P3 -> 173
B8: Total Nivel | D8: =SUM(D6:D7) -> 1 | E8: =SUM(E6:E7) -> 1 | F8: =SUM(F6:F7) -> 0 | G8: =SUM(G6:G7) -> 3 | H8: =SUM(H6:H7) -> 14 | I8: =SUM(I6:I7) -> 2 | J8: =SUM(J6:J7) -> 9 | K8: =SUM(K6:K7) -> 11 | ... O8: =SUM(O6:O7) -> 17 | P8: =SUM(D8:O8) -> 109 | S8: Académicos | T8: =P2+P28 -> 108
B9: Carreras y Programas | C9: Civil | D9: 1 | H9: 12 | J9: 1 | O9: 2 | P9: =SUM(D9:O9) -> 16 | S9: Administrativos | T9: =P4+P30 -> 5
C10: Geología | E10: 1 | G10: 1 | J10: 3 | K10: 8 | N10: 2 | O10: 8 | P10: =SUM(D10:O10) -> 23 | R10: Carreras y Programas | S10: Civil | T10: =P35+P9 -> 87
C11: Minas | H11: 1 | K11: 1 | P11: =SUM(D11:O11) -> 2 | S11: Geología | T11: =P36+P10 -> 45
C12: Petróleos | I12: 1 | J12: 1 | K12: 1 | N12: 42 | O12: 7 | P12: =SUM(D12:O12) -> 52 | S12: Minas | T12: =P37+P11 -> 4
C13: Con-San | H13: 1 | P13: =SUM(D13:O13) -> 1 | S13: Petróleos | T13: =P38+P12 -> 101
C14: Est-Sis | J14: 1 | K14: 1 | L14: 6 | P14: =SUM(D14:O14) -> 8 | S14: Con-San | T14: =P39+P13 -> 13
C15: GeoT | G15: 2 | I15: 1 | J15: 3 | M15: 1 | P15: =SUM(D15:O15) -> 7 | S15: Est-Sis | T15: =P40+P14 -> 16
C16: MSc | P16: =SUM(D16:O16) -> 0 | S16: GeoT | T16: =P41+P15 -> 8
C17: GeoM | P17: =SUM(D17:O17) -> 0 | S17: MSc | T17: =P42+P16 -> 10
C18: MM | P18: =SUM(D18:O18) -> 0 | S18: GeoM | T18: =P43+P17 -> 0
C19: MP | P19: =SUM(D19:O19) -> 0 | S19: MM | T19: =P44+P18 -> 0
B20: Total Carreras y Programas | D20: =SUM(D9:D19) -> 1 | E20: =SUM(E9:E19) -> 1 | F20: =SUM(F9:F19) -> 0 | G20: =SUM(G9:G19) -> 3 | H20: =SUM(H9:H19) -> 14 | I20: =SUM(I9:I19) -> 2 | J20: =SUM(J9:J19) -> 9 | K20: =SUM(K9:K19) -> 11 | ... O20: =SUM(O9:O19) -> 17 | P20: =SUM(D20:O20) -> 109 | S20: MP | T20: =P45+P19 -> 2
B21: Tipo de Actividad | C21: Intercambio Académico | I21: 1 | P21: =SUM(F21:O21) -> 1 | R21: Tipo de Actividad | S21: Intercambio Académico | T21: =P47+P21 -> 9
C22: Asistencia a Eventos | G22: 1 | H22: 1 | J22: 1 | K22: 5 | P22: =SUM(F22:O22) -> 8 | S22: Asistencia a Eventos | T22: =P48+P22 -> 26
C23: Cursos de Formación | D23: 1 | E23: 1 | G23: 2 | H23: 13 | I23: 2 | J23: 2 | K23: 4 | L23: 6 | M23: 1 | N23: 44 | O23: 15 | P23: =SUM(D23:O23) -> 91 | S23: Cursos de Formación | T23: =P49+P23 -> 223
C24: Estancia | J24: 5 | O24: 2 | P24: =SUM(D24:O24) -> 7 | S24: Estancia | T24: =P24 + P50 -> 16
C25: Presentación de trabajos | K25: 2 | P25: =SUM(D25:O25) -> 2 | S25: Presentación de trabajos | T25: =P25 + P51 -> 12
B26: Total Tipo de Actividad | D26: =SUM(D21:D25) -> 1 | E26: =SUM(E21:E25) -> 1 | F26: =SUM(F21:F25) -> 0 | G26: =SUM(G21:G25) -> 3 | H26: =SUM(H21:H25) -> 14 | I26: =SUM(I21:I25) -> 3 | J26: =SUM(J21:J25) -> 8 | K26: =SUM(K21:K25) -> 11 | ... O26: =SUM(O21:O25) -> 17 | P26: =SUM(D26:O26) -> 109 | R26: Modalidad | S26: Virtual | T26: 183
B27: Total Movilidad Entrante | D27: =D26 -> 1 | E27: =E26 -> 1 | F27: =F26 -> 0 | G27: =G26 -> 3 | H27: =H26 -> 14 | I27: =I26 -> 3 | J27: =J26 -> 8 | K27: =K26 -> 11 | ... O27: =O26 -> 17 | P27: =SUM(D27:O27) -> 109 | S27: Presencial | T27: 103
A28: Movilidad Saliente | B28: Categoría | C28: Académico Saliente | D28: 1 | E28: 4 | F28: 3 | G28: 10 | H28: 6 | I28: 3 | J28: 7 | K28: 5 | L28: 6 | M28: 8 | N28: 7 | O28: 5 | P28: =SUM(D28:O28) -> 65
C29: Estudiante Saliente | D29: 27 | E29: 2 | F29: 2 | H29: 26 | I29: 1 | J29: 7 | K29: 10 | M29: 1 | N29: 31 | P29: =SUM(D29:O29) -> 107
C30: Administrativo Saliente | H30: 1 | I30: 1 | J30: 2 | K30: 1 | P30: =SUM(D30:O30) -> 5
B31: Total Categoría | D31: =SUM(D28:D30) -> 28 | E31: =SUM(E28:E30) -> 6 | F31: =SUM(F28:F30) -> 5 | G31: =SUM(G28:G30) -> 10 | H31: =SUM(H28:H30) -> 33 | I31: =SUM(I28:I30) -> 5 | J31: =SUM(J28:J30) -> 16 | K31: =SUM(K28:K30) -> 16 | ... O31: =SUM(O28:O30) -> 5 | P31: =SUM(D31:O31) -> 177
B32: Nivel | C32: Grado | D32: 25 | E32: 4 | F32: 2 | G32: 7 | H32: 27 | I32: 2 | J32: 16 | K32: 8 | L32: 5 | M32: 7 | N32: 38 | O32: 5 | P32: =SUM(D32:O32) -> 146
C33: Postgrado | D33: 3 | E33: 2 | F33: 3 | G33: 3 | H33: 6 | I33: 3 | K33: 8 | L33: 1 | M33: 2 | P33: =SUM(D33:O33) -> 31
B34: Total Nivel | D34: =SUM(D32:D33) -> 28 | E34: =SUM(E32:E33) -> 6 | F34: =SUM(F32:F33) -> 5 | G34: =SUM(G32:G33) -> 10 | H34: =SUM(H32:H33) -> 33 | I34: =SUM(I32:I33) -> 5 | J34: =SUM(J32:J33) -> 16 | K34: =SUM(K32:K33) -> 16 | ... O34: =SUM(O32:O33) -> 5 | P34: =SUM(D34:O34) -> 177
B35: Carreras y Programas | C35: Civil | D35: 25 | E35: 2 | F35: 2 | G35: 3 | H35: 25 | I35: 1 | J35: 2 | K35: 3 | L35: 2 | M35: 3 | N35: 3 | P35: =SUM(D35:O35) -> 71
C36: Geología | E36: 2 | G36: 4 | H36: 1 | I36: 1 | J36: 1 | K36: 4 | L36: 2 | M36: 3 | O36: 4 | P36: =SUM(D36:O36) -> 22
C37: Minas | D37: 1 | K37: 1 | P37: =SUM(D37:O37) -> 2
C38: Petróleos | H38: 1 | J38: 10 | L38: 1 | M38: 1 | N38: 35 | O38: 1 | P38: =SUM(D38:O38) -> 49
C39: Con-San | H39: 4 | I39: 1 | K39: 6 | M39: 1 | P39: =SUM(D39:O39) -> 12
C40: Est-Sis | E40: 2 | G40: 3 | J40: 3 | P40: =SUM(D40:O40) -> 8
...

Sheet Países 2025
B1: Movilidad Entrante | F1: Movilidad Saliente
B2: Country | C2: Modality | D2: Count | F2: Country | G2: Modality | H2: Count
B3: Colombia | C3: Virtual | D3: 51 | F3: Argentina | G3: Virtual | H3: 13
B4: Spain | C4: In person | D4: 7 | F4: Brasil | G4: in person | H4: 14
B5: Italy | C5: In person | D5: 9 | F5: Canada | G5: in person | H5: 3
B6: Russia | C6: Virtual | D6: 1 | F6: Chile | G6: Virtual | H6: 2
B7: Mexico | C7: Virtual | D7: 2 | F7: China | G7: in person | H7: 2
B8: United Kingdom | C8: In person | D8: 1 | F8: Colombia | G8: in person | H8: 8
B9: United States | C9: Virtual | D9: 1 | F9: Morocco | G9: in person | H9: 1
B10: Peru | C10: Virtual | D10: 12 | F10: Colombia | G10: Virtual | H10: 32
B11: Germany | C11: Virtual | D11: 4 | F11: Spain | G11: in person | H11: 13
B12: Germany | C12: In person | D12: 1 | F12: United States | G12: in person | H12: 13
B13: Argentina | C13: Virtual | D13: 1 | F13: Brasil | G13: Virtual | H13: 1
B14: Brasil | C14: Virtual | D14: 8 | F14: Guatemala | G14: in person | H14: 1
... B18: Colombia | C18: In person | D18: 1 | F18: Belgium | G18: in person | H18: 1
B19: Guatemala | C19: In person | D19: 2
B20: Bolivia | C20: Virtual | D20: 1
B21: Bolivia | C21: In person | D21: 1
B22: United States | C22: In person | D22: 1
B23: Total | D23: =SUM(D3:D22) -> 108 | F23: United States | G23: Virtual | H23: 2
F24: Malaysia | G24: in person | H24: 4
F25: Norway | G25: in person | H25: 2
F26: Netherlands | G26: in person | H26: 1
F27: Panama | G27: in person | H27: 6
F28: Peru | G28: in person | H28: 2
F29: Peru | G29: Virtual | H29: 25
F30: Mexico | G30: Virtual | H30: 23
F31: Bolivia | G31: in person | H31: 1
F32: Australia | G32: in person | H32: 2
F33: Austria | G33: in person | H33: 1
F34: Italy | G34: in person | H34: 2
F35: Total | H35: =SUM(H3:H34) -> 178

Sheet Comparativa 2022 - 2025
B1: Movilidad Académica FICT 2022 | G1: Movilidad Académica FICT 2023 | L1: Movilidad Académica FICT 2024 | Q1: Movilidad Académica FICT 2025
B2: Resumen 2022 | E2: Total | G2: Resumen por año | J2: Total | L2: Resumen por año | O2: Total | Q2: Resumen por año 04 de Septiembre | T2: Total
B3: Tipo de movilidad | C3: Movilidad Entrante | D3: ='Movilidad FICT 2022'!T3 -> 7 | E3: =SUM(D22:D26) -> 14 | G3: Tipo de movilidad | H3: Movilidad Entrante | I3: ='Movilidad FICT 2023'!T3 -> 55 | J3: =I3+I4 -> 97 | L3: Tipo de movilidad | M3: Movilidad Entrante | N3: ='Movilidad FICT 2024'!T3 -> 66 | O3: =SUM(N21:N25) -> 144 | Q3: Tipo de movilidad | R3: Movilidad Entrante | S3: ='Movilidad FICT 2025'!T3 -> 109 | T3: =SUM(S21:S25) -> 286
C4: Movilidad Saliente | D4: ='Movilidad FICT 2022'!T4 -> 7 | H4: Movilidad Saliente | I4: ='Movilidad FICT 2023'!T4 -> 42 | M4: Movilidad Saliente | N4: ='Movilidad FICT 2024'!T4 -> 78 | R4: Movilidad Saliente | S4: ='Movilidad FICT 2025'!T4 -> 177
B5: Nivel | C5: Grado | D5: ='Movilidad FICT 2022'!T5 -> 11 | G5: Nivel | H5: Grado | I5: ='Movilidad FICT 2023'!T5 -> 93 | L5: Nivel | M5: Grado | N5: ='Movilidad FICT 2024'!T5 -> 111 | Q5: Nivel | R5: Grado | S5: ='Movilidad FICT 2025'!T5 -> 238
C6: Postgrado | D6: ='Movilidad FICT 2022'!T6 -> 1 | H6: Postgrado | I6: ='Movilidad FICT 2023'!T6 -> 4 | M6: Postgrado | N6: ='Movilidad FICT 2024'!T6 -> 33 | R6: Postgrado | S6: ='Movilidad FICT 2025'!T6 -> 48
B7: Categoría | C7: Estudiantes | D7: ='Movilidad FICT 2022'!T7 -> 1 | G7: Categoría | H7: Estudiantes | I7: ='Movilidad FICT 2023'!T7 -> 89 | L7: Categoría | M7: Estudiantes | N7: ='Movilidad FICT 2024'!T7 -> 95 | Q7: Categoría | R7: Estudiantes | S7: ='Movilidad FICT 2025'!T7 -> 173
C8: Académicos | D8: ='Movilidad FICT 2022'!T8 -> 12 | H8: Académicos | I8: ='Movilidad FICT 2023'!T8 -> 8 | M8: Académicos | N8: ='Movilidad FICT 2024'!T8 -> 47 | R8: Académicos | S8: ='Movilidad FICT 2025'!T8 -> 108
C9: Administrativos | D9: ='Movilidad FICT 2022'!T9 -> 1 | H9: Administrativos | I9: 0 | M9: Administrativos | N9: ='Movilidad FICT 2024'!T9 -> 2 | R9: Administrativos | S9: ='Movilidad FICT 2025'!T9 -> 5
B10: Carreras y Programas | C10: Civil | D10: ='Movilidad FICT 2022'!T10 -> 4 | G10: Carreras y Programas | H10: Civil | I10: ='Movilidad FICT 2023'!T10 -> 75 | L10: Carreras y Programas | M10: Civil | N10: ='Movilidad FICT 2024'!T10 -> 42 | Q10: Carreras y Programas | R10: Civil | S10: ='Movilidad FICT 2025'!T10 -> 87
C11: Geología | D11: ='Movilidad FICT 2022'!T11 -> 1 | H11: Geología | I11: ='Movilidad FICT 2023'!T11 -> 12 | M11: Geología | N11: ='Movilidad FICT 2024'!T11 -> 5 | R11: Geología | S11: ='Movilidad FICT 2025'!T11 -> 45
C12: Minas | D12: ='Movilidad FICT 2022'!T12 -> 0 | H12: Minas | I12: ='Movilidad FICT 2023'!T12 -> 1 | M12: Minas | N12: ='Movilidad FICT 2024'!T12 -> 5 | R12: Minas | S12: ='Movilidad FICT 2025'!T12 -> 4
C13: Petróleos | D13: ='Movilidad FICT 2022'!T13 -> 1 | H13: Petróleos | I13: ='Movilidad FICT 2023'!T13 -> 5 | M13: Petróleos | N13: ='Movilidad FICT 2024'!T13 -> 59 | R13: Petróleos | S13: ='Movilidad FICT 2025'!T13 -> 101
C14: Con-San | D14: ='Movilidad FICT 2022'!T14 -> 1 | H14: Con-San | I14: ='Movilidad FICT 2023'!T14 -> 0 | M14: Con-San | N14: ='Movilidad FICT 2024'!T14 -> 26 | R14: Con-San | S14: ='Movilidad FICT 2025'!T14 -> 13
C15: Est-Sis | D15: ='Movilidad FICT 2022'!T15 -> 0 | H15: Est-Sis | I15: ='Movilidad FICT 2023'!T15 -> 0 | M15: Est-Sis | N15: ='Movilidad FICT 2024'!T15 -> 1 | R15: Est-Sis | S15: ='Movilidad FICT 2025'!T15 -> 16
C16: GeoT | D16: ='Movilidad FICT 2022'!T16 -> 0 | H16: GeoT | I16: ='Movilidad FICT 2023'!T16 -> 4 | M16: GeoT | N16: ='Movilidad FICT 2024'!T16 -> 3 | R16: GeoT | S16: ='Movilidad FICT 2025'!T16 -> 8
C17: MSc | D17: ='Movilidad FICT 2022'!T17 -> 0 | H17: MSc | I17: ='Movilidad FICT 2023'!T17 -> 0 | M17: MSc | N17: ='Movilidad FICT 2024'!T17 -> 1 | R17: MSc | S17: ='Movilidad FICT 2025'!T17 -> 10
C18: GeoM | D18: ='Movilidad FICT 2022'!T18 -> 0 | H18: GeoM | I18: ='Movilidad FICT 2023'!T18 -> 0 | M18: GeoM | N18: ='Movilidad FICT 2024'!T18 -> 0 | R18: GeoM | S18: ='Movilidad FICT 2025'!T18 -> 0
C19: MM | D19: ='Movilidad FICT 2022'!T19 -> 0 | H19: MM | I19: ='Movilidad FICT 2023'!T19 -> 0 | M19: MM | N19: ='Movilidad FICT 2024'!T19 -> 2 | R19: MM | S19: ='Movilidad FICT 2025'!T19 -> 0
C20: Proyecto CCUS | D20: ='Movilidad FICT 2022'!T20 -> 7 | H20: MP | I20: ='Movilidad FICT 2023'!T20 -> 0 | M20: MP | N20: ='Movilidad FICT 2024'!T20 -> 0 | R20: MP | S20: ='Movilidad FICT 2025'!T20 -> 2
C21: PP | D21: ='Movilidad FICT 2022'!T21 -> 0 | G21: Tipo de Actividad | H21: Intercambio Académico | I21: ='Movilidad FICT 2023'!T21 -> 26 | L21: Tipo de Actividad | M21: Intercambio Académico | N21: ='Movilidad FICT 2024'!T21 -> 3 | Q21: Tipo de Actividad | R21: Intercambio Académico | S21: ='Movilidad FICT 2025'!T21 -> 9
B22: Tipo de Actividad | C22: Intercambio Académico | D22: ='Movilidad FICT 2022'!T22 -> 0 | H22: Asistencia a Eventos | I22: ='Movilidad FICT 2023'!T22 -> 2 | M22: Asistencia a Eventos | N22: ='Movilidad FICT 2024'!T22 -> 15 | R22: Asistencia a Eventos | S22: ='Movilidad FICT 2025'!T22 -> 26
C23: Asistencia a Eventos | D23: ='Movilidad FICT 2022'!T23 -> 8 | H23: Cursos de Formación | I23: ='Movilidad FICT 2023'!T23 -> 69 | M23: Cursos de Formación | N23: ='Movilidad FICT 2024'!T23 -> 92 | R23: Cursos de Formación | S23: ='Movilidad FICT 2025'!T23 -> 223
C24: Cursos de Formación | D24: ='Movilidad FICT 2022'!T24 -> 5 | H24: Estancia | I24: 0 | M24: Estancia | N24: ='Movilidad FICT 2024'!T24 -> 29 | R24: Estancia | S24: ='Movilidad FICT 2025'!T24 -> 16
C25: Estancia | D25: ='Movilidad FICT 2022'!T25 -> 1 | H25: Presentación de Trabajos | I25: 0 | M25: Presentación de Trabajos | N25: ='Movilidad FICT 2024'!T25 -> 5 | R25: Presentación de trabajos | S25: ='Movilidad FICT 2025'!T25 -> 12
C26: Presentación de trabajos | D26: ='Movilidad FICT 2022'!T26 -> 0 | G26: Modalidad | H26: Virtual | I26: ='Movilidad FICT 2023'!T26 -> 57 | L26: Modalidad | M26: Virtual | N26: ='Movilidad FICT 2024'!T26 -> 97 | Q26: Modalidad | R26: Virtual | S26: ='Movilidad FICT 2025'!T26 -> 183
B27: Modalidad | C27: Virtual | D27: ='Movilidad FICT 2022'!T27 -> 2 | H27: Presencial | I27: ='Movilidad FICT 2023'!T27 -> 40 | M27: Presencial | N27: ='Movilidad FICT 2024'!T27 -> 47 | R27: Presencial | S27: ='Movilidad FICT 2025'!T27 -> 103
C28: Presencial | D28: ='Movilidad FICT 2022'!T28 -> 12
A60: Nota: Al corte actual (mayo 2024), se han tenido aproximadamente el 50% de las movilizaciones que fueron registradas en el año 2023.

Sheet Modalidades
C3: enero | D3: febrero | E3: marzo | F3: abril | G3: mayo | H3: junio | I3: julio | J3: agosto | K3: septiembre | L3: octubre | M3: noviembre | N3: diciembre
C4: 2 | D4: 2 | H4: 1 | L4: 2
D7: saliente
C8: enero | D8: febrero | E8: marzo | F8: abril | G8: mayo | H8: junio | I8: julio | J8: agosto | K8: septiembre | L8: octubre | M8: noviembre | N8: diciembre
C9: 2 | D9: 1 | E9: 1 | F9: 10 | G9: 5 | H9: 4 | I9: 22 | K9: 1 | L9: 1
